import copy

import pytest

from p2p.exceptions import (
    HandshakeFailure,
    HandshakeFailureTooManyPeers,
    MalformedMessage,
    NoMatchingPeerCapabilities,
)
from p2p.peer_pool import COMMON_PEER_CONNECTION_EXCEPTIONS
from p2p.tracking.connection import (
    get_timeout_for_failure,
    register_error,
)


@pytest.fixture(autouse=True)
def _prevent_global_mutation_of_registry():
    # Ensure that the tests don't result in mutation of the configuration of
    # timeout failures.
    from p2p.tracking import connection
    original = copy.copy(connection.FAILURE_TIMEOUTS)
    yield
    # We cannot simply replace the original object onto the module because
    # there are functions which maintain a reference to the original object
    # which means it has to be updated in-place.
    keys_to_pop = set(connection.FAILURE_TIMEOUTS.keys()).difference(original.keys())
    for key in keys_to_pop:
        connection.FAILURE_TIMEOUTS.pop(key)
    for key, value in original.items():
        connection.FAILURE_TIMEOUTS[key] = value
    # Validate that it is back to the original state
    assert connection.FAILURE_TIMEOUTS == original


def test_get_timeout_for_common_handshake_exceptions():
    common_exc_types = COMMON_PEER_CONNECTION_EXCEPTIONS + (
        HandshakeFailure, HandshakeFailureTooManyPeers, MalformedMessage,
        NoMatchingPeerCapabilities)
    for exc_type in common_exc_types:
        assert get_timeout_for_failure(exc_type()) <= (60 * 60)


def test_get_timeout_for_failure_with_unknown_exception():
    class UnknownException(Exception):
        pass

    with pytest.raises(Exception, match="Unknown failure type"):
        get_timeout_for_failure(UnknownException())


def test_get_timeout_for_failure_with_3rd_party_exception():
    class UnknownException(Exception):
        pass

    # verify it isn't yet registered
    with pytest.raises(Exception, match="Unknown failure type"):
        get_timeout_for_failure(UnknownException())

    register_error(UnknownException, 1234)

    assert get_timeout_for_failure(UnknownException()) == 1234
